<?xml version="1.0"?>
<robot xmlns:xacro="http://ros.org/wiki/xacro">
  <xacro:macro name="abb_irb6700_200_260" params="prefix">
    <xacro:include filename="$(find abb_resources)/urdf/common_materials.xacro"/>
    <!-- link list -->
    <link name="world" />
    <joint name="${prefix}world_base_link" type="fixed">
        <parent link="world" />
        <child link="${prefix}base_link" />
        <origin rpy="0 0 0" xyz="-2.5 0 0" />
    </joint>

    <link name="${prefix}base_link">
      <visual>
        <origin xyz="0 0 0" rpy="0 0 0" />
        <geometry>
          <mesh filename="package://abb_irb6700_support/meshes/irb6700/visual/base_link.stl" />
        </geometry>
        <xacro:material_abb_white/>
      </visual>
      <collision>
        <origin xyz="0 0 0" rpy="0 0 0" />
        <geometry>
          <mesh filename="package://abb_irb6700_support/meshes/irb6700/collision/base_link.stl" />
        </geometry>
        <xacro:material_abb_yellow/>
      </collision>
    </link>
    <link name="${prefix}link_1">
      <visual>
        <origin xyz="0 0 0" rpy="0 0 0" />
        <geometry>
          <mesh filename="package://abb_irb6700_support/meshes/irb6700/visual/link_1.stl" />
        </geometry>
        <xacro:material_abb_white/>
      </visual>
      <collision>
        <origin xyz="0 0 0" rpy="0 0 0" />
        <geometry>
          <mesh filename="package://abb_irb6700_support/meshes/irb6700/collision/link_1.stl" />
        </geometry>
        <xacro:material_abb_yellow/>
      </collision>
    </link>
    <link name="${prefix}cylinder">
      <visual>
        <origin xyz="0 0 0" rpy="0 0 0" />
        <geometry>
          <mesh filename="package://abb_irb6700_support/meshes/irb6700/visual/cylinder.stl" />
        </geometry>
        <xacro:material_abb_white/>
      </visual>
      <collision>
        <origin xyz="0 0 0" rpy="0 0 0" />
        <geometry>
          <mesh filename="package://abb_irb6700_support/meshes/irb6700/collision/cylinder.stl" />
        </geometry>
        <xacro:material_abb_yellow/>
      </collision>
    </link>
    <link name="${prefix}piston">
      <visual>
        <origin xyz="0 0 0" rpy="0 0 0" />
        <geometry>
          <mesh filename="package://abb_irb6700_support/meshes/irb6700/visual/piston.stl" />
        </geometry>
        <xacro:material_abb_white/>
      </visual>
      <collision>
        <origin xyz="0 0 0" rpy="0 0 0" />
        <geometry>
          <mesh filename="package://abb_irb6700_support/meshes/irb6700/collision/piston.stl" />
        </geometry>
        <xacro:material_abb_yellow/>
      </collision>
    </link>
    <link name="${prefix}link_2">
      <visual>
        <origin xyz="0 0 0" rpy="0 0 0" />
        <geometry>
          <mesh filename="package://abb_irb6700_support/meshes/irb6700_200_260/visual/link_2.stl" />
        </geometry>
        <xacro:material_abb_white/>
      </visual>
      <collision>
        <origin xyz="0 0 0" rpy="0 0 0" />
        <geometry>
          <mesh filename="package://abb_irb6700_support/meshes/irb6700_200_260/collision/link_2.stl" />
        </geometry>
        <xacro:material_abb_yellow/>
      </collision>
    </link>
    <link name="${prefix}link_3">
      <visual>
        <origin xyz="0 0 0" rpy="0 0 0" />
        <geometry>
          <mesh filename="package://abb_irb6700_support/meshes/irb6700_200_260/visual/link_3.stl" />
        </geometry>
        <xacro:material_abb_white/>
      </visual>
      <collision>
        <origin xyz="0 0 0" rpy="0 0 0" />
        <geometry>
          <mesh filename="package://abb_irb6700_support/meshes/irb6700_200_260/collision/link_3.stl" />
        </geometry>
        <xacro:material_abb_yellow/>
      </collision>
    </link>
    <link name="${prefix}link_4">
      <visual>
        <origin xyz="0 0 0" rpy="0 0 0" />
        <geometry>
          <mesh filename="package://abb_irb6700_support/meshes/irb6700_200_260/visual/link_4.stl" />
        </geometry>
        <xacro:material_abb_white/>
      </visual>
      <collision>
        <origin xyz="0 0 0" rpy="0 0 0" />
        <geometry>
          <mesh filename="package://abb_irb6700_support/meshes/irb6700_200_260/collision/link_4.stl" />
        </geometry>
        <xacro:material_abb_yellow/>
      </collision>
    </link>
    <link name="${prefix}link_5">
      <visual>
        <origin xyz="0 0 0" rpy="0 0 0" />
        <geometry>
          <mesh filename="package://abb_irb6700_support/meshes/irb6700/visual/link_5.stl" />
        </geometry>
        <xacro:material_abb_white/>
      </visual>
      <collision>
        <origin xyz="0 0 0" rpy="0 0 0" />
        <geometry>
          <mesh filename="package://abb_irb6700_support/meshes/irb6700/collision/link_5.stl" />
        </geometry>
        <xacro:material_abb_yellow/>
      </collision>
    </link>
    <link name="${prefix}link_6">
      <visual>
        <origin xyz="0 0 0" rpy="0 0 0" />
        <geometry>
          <mesh filename="package://abb_irb6700_support/meshes/irb6700/visual/link_6.stl" />
        </geometry>
        <xacro:material_abb_white/>
      </visual>
      <collision>
        <origin xyz="0 0 0" rpy="0 0 0" />
        <geometry>
          <mesh filename="package://abb_irb6700_support/meshes/irb6700/collision/link_6.stl" />
        </geometry>
        <xacro:material_abb_yellow/>
      </collision>
    </link>
    <!--add e-e-->
    <link name="${prefix}ef">
	  <visual>
	    <origin xyz="0 0 0" rpy="0 0 0"/>
	    <geometry>
	      <mesh filename="package://fanuc_r2000ic_support/meshes/r2000ic165f/visual/ef.stl"/>
	    </geometry>
	    <xacro:material_abb_yellow />
	  </visual>
	  <collision>
	    <origin xyz="0 0 0" rpy="0 0 0"/>
	    <geometry>
	      <mesh filename="package://fanuc_r2000ic_support/meshes/r2000ic165f/collision/ef.stl"/>
	    </geometry>
	  </collision>
	  <inertial>
	     <mass value="3.0" />
	     <origin rpy="0 0 0" xyz="0.0 0.0 0.0" />
	     <inertia ixx="0" ixy="0" ixz="0" iyy="0" iyz="0" izz="0" />
	  </inertial>
    </link>


    <joint name="${prefix}joint_1" type="revolute">
      <origin xyz="0 0 0.78" rpy="0 0 0" />
      <parent link="${prefix}base_link" />
      <child link="${prefix}link_1" />
      <axis xyz="0 0 1" />
      <limit lower="-${radians(170)}" upper="${radians(170)}" effort="0" velocity="${radians(110)}" />
    </joint>
    <joint name="${prefix}joint_2" type="revolute">
      <origin xyz="0.32 0 0" rpy="0 0 0" />
      <parent link="${prefix}link_1" />
      <child link="${prefix}link_2" />
      <axis xyz="0 1 0" />
      <limit lower="-${radians(65)}" upper="${radians(85)}" effort="0" velocity="${radians(110)}" />
    </joint>
    <joint name="${prefix}joint_3" type="revolute">
      <origin xyz="0 0 1.125" rpy="0 0 0" />
      <parent link="${prefix}link_2" />
      <child link="${prefix}link_3" />
      <axis xyz="0 1 0" />
      <limit lower="-${radians(180)}" upper="${radians(70)}" effort="0" velocity="${radians(110)}" />
    </joint>
    <joint name="${prefix}joint_4" type="revolute">
      <origin xyz="0 0 0.2" rpy="0 0 0" />
      <parent link="${prefix}link_3" />
      <child link="${prefix}link_4" />
      <axis xyz="1 0 0" />
      <limit lower="-${radians(300)}" upper="${radians(300)}" effort="0" velocity="${radians(190)}" />
    </joint>
    <joint name="${prefix}joint_5" type="revolute">
      <origin xyz="1.1425 0 0" rpy="0 0 0" />
      <parent link="${prefix}link_4" />
      <child link="${prefix}link_5" />
      <axis xyz="0 1 0" />
      <limit lower="-${radians(130)}" upper="${radians(130)}" effort="0" velocity="${radians(150)}" />
    </joint>
    <joint name="${prefix}joint_6" type="revolute">
      <origin xyz="0.2 0 0" rpy="0 0 0" />
      <parent link="${prefix}link_5" />
      <child link="${prefix}link_6" />
      <axis xyz="1 0 0" />
      <limit lower="-${radians(360)}" upper="${radians(360)}" effort="0" velocity="${radians(210)}" />
    </joint>
    <joint name="${prefix}cylinder_joint" type="revolute">
      <origin xyz="-0.349 -0.194 -0.142" rpy="0 0 0" />
      <parent link="${prefix}link_1" />
      <child link="${prefix}cylinder" />
      <axis xyz="0 1 0" />
      <mimic joint="${prefix}joint_2" multiplier="-0.25"/>
      <limit lower="-${radians(65*0.25)}" upper="${radians(85*0.25)}" effort="0" velocity="100" />
    </joint>
    <joint name="${prefix}piston_joint" type="prismatic">
      <origin xyz="0 0 0" rpy="0.20897 0 -${radians(90)}" />
      <parent link="${prefix}cylinder" />
      <child link="${prefix}piston" />
      <axis xyz="0 1 0" />
      <mimic joint="${prefix}joint_2" multiplier="0.15"/>
      <limit lower="-0.25" upper="0.25" effort="0" velocity="100" />
    </joint>

    <!-- ROS-Industrial 'base' frame: base_link to ABB World Coordinates transform -->
    <link name="${prefix}base" />
    <joint name="${prefix}base_link-base" type="fixed">
      <origin xyz="0 0 0" rpy="0 0 0"/>
      <parent link="${prefix}base_link"/>
      <child link="${prefix}base"/>
    </joint>

    <!-- ROS-Industrial 'flange' frame: attachment point for EEF models -->
    <link name="${prefix}flange"/>
    <joint type="fixed" name="${prefix}joint_6-flange">
      <origin xyz="0 0 0" rpy="0 0 0"/>
      <parent link="${prefix}link_6"/>
      <child link="${prefix}flange"/>
    </joint>

    <!-- ROS-Industrial 'tool0' frame: all-zeros tool frame -->
    <link name="${prefix}tool0" />
    <joint name="${prefix}link_6-tool0" type="fixed">
      <origin xyz="0 0 0" rpy="0 ${radians(90)} 0" />
      <parent link="${prefix}flange" />
      <child link="${prefix}tool0" />
    </joint>

    <joint name="${prefix}flange-ef" type="fixed">
      <origin xyz="0 0 0" rpy="${radians(180)} ${radians(-180)} 0" />
      <parent link="${prefix}tool0" />
      <child link="${prefix}ef" />
    </joint>

    <link name="${prefix}tcp" />
    <joint name="${prefix}tcp_ef" type="fixed">
      <origin xyz="-0.204433413 -7.32E-04 0.333181177" rpy="5.53832e-13 -0.785398 0"/>
      <parent link="${prefix}ef" />
      <child link="${prefix}tcp" />
    </joint>



    <!-- Transmission part -->
	<transmission name="trans_joint_1">
        <type>transmission_interface/SimpleTransmission</type>
        <joint name="${prefix}joint_1">
            <hardwareInterface>hardware_interface/EffortJointInterface</hardwareInterface>
        </joint>
        <actuator name="joint_1_motor">
            <hardwareInterface>hardware_interface/EffortJointInterface</hardwareInterface>
            <mechanicalReduction>1</mechanicalReduction>
        </actuator>
    </transmission>

	<transmission name="trans_joint_2">
		<type>transmission_interface/SimpleTransmission</type>
		<joint name="${prefix}joint_2">
		    <hardwareInterface>hardware_interface/EffortJointInterface</hardwareInterface>
		</joint>
		<actuator name="joint_2_motor">
		    <hardwareInterface>hardware_interface/EffortJointInterface</hardwareInterface>
		    <mechanicalReduction>1</mechanicalReduction>
		</actuator>
	</transmission>

	<transmission name="trans_joint_3">
		<type>transmission_interface/SimpleTransmission</type>
		<joint name="${prefix}joint_3">
		    <hardwareInterface>hardware_interface/EffortJointInterface</hardwareInterface>
		</joint>
		<actuator name="joint_3_motor">
		    <hardwareInterface>hardware_interface/EffortJointInterface</hardwareInterface>
		    <mechanicalReduction>1</mechanicalReduction>
		</actuator>
	</transmission>

	<transmission name="trans_joint_4">
		<type>transmission_interface/SimpleTransmission</type>
		<joint name="${prefix}joint_4">
		    <hardwareInterface>hardware_interface/EffortJointInterface</hardwareInterface>
		</joint>
		<actuator name="joint_4_motor">
		    <hardwareInterface>hardware_interface/EffortJointInterface</hardwareInterface>
		    <mechanicalReduction>1</mechanicalReduction>
		</actuator>
	</transmission>

	<transmission name="trans_joint_5">
		<type>transmission_interface/SimpleTransmission</type>
		<joint name="${prefix}joint_5">
		    <hardwareInterface>hardware_interface/EffortJointInterface</hardwareInterface>
		</joint>
		<actuator name="joint_5_motor">
		    <hardwareInterface>hardware_interface/EffortJointInterface</hardwareInterface>
		    <mechanicalReduction>1</mechanicalReduction>
		</actuator>
	</transmission>

	<transmission name="trans_joint_6">
		<type>transmission_interface/SimpleTransmission</type>
		<joint name="${prefix}joint_6">
		    <hardwareInterface>hardware_interface/EffortJointInterface</hardwareInterface>
		</joint>
		<actuator name="joint_6_motor">
		    <hardwareInterface>hardware_interface/EffortJointInterface</hardwareInterface>
		    <mechanicalReduction>1</mechanicalReduction>
		</actuator>
	</transmission>

    <gazebo reference="${prefix}base_link">
        <selfCollide>true</selfCollide>
    </gazebo>
    <gazebo reference="${prefix}link_1">
        <selfCollide>true</selfCollide>
    </gazebo>
    <gazebo reference="${prefix}link_2">
        <selfCollide>true</selfCollide>
    </gazebo>
    <gazebo reference="${prefix}link_3">
        <selfCollide>true</selfCollide>
    </gazebo>
    <gazebo reference="${prefix}link_4">
        <selfCollide>true</selfCollide>
    </gazebo>
    <gazebo reference="${prefix}link_5">
        <selfCollide>true</selfCollide>
    </gazebo>
    <gazebo reference="${prefix}link_6">
        <selfCollide>true</selfCollide>
    </gazebo>

    <gazebo reference="${prefix}tool0">
        <selfCollide>true</selfCollide>
    </gazebo>

    <gazebo reference="${prefix}flange">
        <selfCollide>true</selfCollide>
    </gazebo>

	<gazebo reference="${prefix}gazebo_camera_link">
        <sensor type="depth" name="sensor_name">
          <!-- Set always_on only sensor, not on plugin -->
          <always_on>1</always_on>
          <!-- Set update_rate only sensor, not on plugin -->
          <update_rate>5</update_rate>
          <camera name="camera_name">
            <image>
              <width>320</width>
              <height>200</height>
            </image>
            <distortion>
              <k1>-0.0</k1>
              <k2>0.0</k2>
              <k3>0.0</k3>
              <p1>-0.0</p1>
              <p2>-0.0</p2>
              <center>0.5 0.5</center>
            </distortion>
          </camera>
          <plugin name="plugin_name" filename="libgazebo_ros_camera.so">
            <!-- Change namespace, camera name and topics so:
                 * Raw images are published to: /custom_ns/custom_camera/custom_image
                 * Depth images are published to: /custom_ns/custom_camera/custom_image_depth
                 * Raw image camera info is published to: /custom_ns/custom_camera/custom_info_raw
                 * Depth image camera info is published to: /custom_ns/custom_camera/custom_info_depth
                 * Point cloud is published to: /custom_ns/custom_camera/custom_points
            -->
            <ros>
              <namespace>custom_ns</namespace>
              <argument>camera/image_raw:=camera/custom_image</argument>
              <argument>camera/image_depth:=camera/custom_image_depth</argument>
              <argument>camera/camera_info:=camera/custom_info_raw</argument>
              <argument>camera/camera_info_depth:=camera/custom_info_depth</argument>
              <argument>camera/points:=camera/pointcloud</argument>
            </ros>
            <!-- Set camera name. If empty, defaults to sensor name (i.e. "sensor_name") -->
            <camera_name>camera</camera_name>
            <frame_name>camera_link_optical</frame_name>
            <!-- Set TF frame name. If empty, defaults to link name (i.e. "link_name") -->
            <hack_baseline>0.07</hack_baseline>
            <!-- No need to repeat distortion parameters or to set autoDistortion -->
             <min_depth>0.1</min_depth>
          </plugin>
        </sensor>
    </gazebo>

    <gazebo>

        <plugin name='gazebo_ros_joint_state_publisher' filename='libgazebo_ros_joint_state_publisher.so'>
          <ros>
              <namespace>/test</namespace>
              <argument>joint_states:=joint_states</argument>
	     
          </ros>
          <update_rate>50</update_rate>

          <joint_name>${prefix}joint_1</joint_name>
          <joint_name>${prefix}joint_2</joint_name>
          <joint_name>${prefix}joint_3</joint_name>
          <joint_name>${prefix}joint_4</joint_name>
          <joint_name>${prefix}joint_5</joint_name>
          <joint_name>${prefix}joint_6</joint_name>

        </plugin>

        <plugin name='crs_gazebo_plugins_joint_pose_trajectory' filename='libcrs_gazebo_plugins_joint_pose_trajectory.so'>
            <ros>
              <namespace>sim</namespace>
              <argument>follow_joint_trajectory:=${prefix}follow_joint_trajectory</argument>
            </ros>
            <update_rate>20</update_rate>
        </plugin>
    </gazebo>

  </xacro:macro>
</robot>
