<?xml version="1.0"?>
<robot xmlns:xacro="http://ros.org/wiki/xacro">
  <xacro:include filename="$(find fanuc_resources)/urdf/common_materials.xacro"/>

  <xacro:macro name="fanuc_r2000ic125l" params="prefix">
    <!-- link list -->
    <link name="${prefix}base_link">
      <visual>
        <origin xyz="0 0 0" rpy="0 0 0"/>
        <geometry>
          <mesh filename="package://fanuc_r2000ic_support/meshes/r2000ic125l/visual/base_link.stl"/>
        </geometry>
        <xacro:material_fanuc_gray31 />
      </visual>
      <collision>
        <geometry>
          <mesh filename="package://fanuc_r2000ic_support/meshes/r2000ic125l/collision/base_link.stl"/>
        </geometry>
        <xacro:material_fanuc_gray31 />
      </collision>
    </link>
    <link name="${prefix}link_1">
      <visual>
        <origin xyz="0 0 0" rpy="0 0 0"/>
        <geometry>
          <mesh filename="package://fanuc_r2000ic_support/meshes/r2000ic125l/visual/link_1.stl"/>
        </geometry>
        <xacro:material_fanuc_yellow />
      </visual>
      <collision>
        <origin xyz="0 0 0" rpy="0 0 0"/>
        <geometry>
          <mesh filename="package://fanuc_r2000ic_support/meshes/r2000ic125l/collision/link_1.stl"/>
        </geometry>
        <xacro:material_fanuc_yellow />
      </collision>
    </link>
    <link name="${prefix}link_2">
      <visual>
        <origin xyz="0 0 0" rpy="0 0 0"/>
        <geometry>
          <mesh filename="package://fanuc_r2000ic_support/meshes/r2000ic125l/visual/link_2.stl"/>
        </geometry>
        <xacro:material_fanuc_yellow />
      </visual>
      <collision>
        <origin xyz="0 0 0" rpy="0 0 0"/>
        <geometry>
          <mesh filename="package://fanuc_r2000ic_support/meshes/r2000ic125l/collision/link_2.stl"/>
        </geometry>
        <xacro:material_fanuc_yellow />
      </collision>
    </link>
    <link name="${prefix}link_3">
      <visual>
        <origin xyz="0 0 0" rpy="0 0 0"/>
        <geometry>
          <mesh filename="package://fanuc_r2000ic_support/meshes/r2000ic125l/visual/link_3.stl"/>
        </geometry>
        <xacro:material_fanuc_yellow />
      </visual>
      <collision>
        <origin xyz="0 0 0" rpy="0 0 0"/>
        <geometry>
          <mesh filename="package://fanuc_r2000ic_support/meshes/r2000ic125l/collision/link_3.stl"/>
        </geometry>
        <xacro:material_fanuc_yellow />
      </collision>
    </link>
    <link name="${prefix}link_4">
      <visual>
        <origin xyz="1.730 0 0" rpy="0 0 0"/>
        <geometry>
          <mesh filename="package://fanuc_r2000ic_support/meshes/r2000ic125l/visual/link_4.stl"/>
        </geometry>
        <xacro:material_fanuc_yellow />
      </visual>
      <collision>
        <origin xyz="1.730 0 0" rpy="0 0 0"/>
        <geometry>
          <mesh filename="package://fanuc_r2000ic_support/meshes/r2000ic125l/collision/link_4.stl"/>
        </geometry>
        <xacro:material_fanuc_yellow />
      </collision>
    </link>
    <link name="${prefix}link_5">
      <visual>
        <origin xyz="0 0 0" rpy="0 0 0"/>
        <geometry>
          <mesh filename="package://fanuc_r2000ic_support/meshes/r2000ic125l/visual/link_5.stl"/>
        </geometry>
        <xacro:material_fanuc_yellow />
      </visual>
      <collision>
        <origin xyz="0 0 0" rpy="0 0 0"/>
        <geometry>
          <mesh filename="package://fanuc_r2000ic_support/meshes/r2000ic125l/collision/link_5.stl"/>
        </geometry>
        <xacro:material_fanuc_yellow />
      </collision>
    </link>
    <link name="${prefix}link_6">
      <visual>
        <origin xyz="0 0 0" rpy="0 0 0"/>
        <geometry>
          <mesh filename="package://fanuc_r2000ic_support/meshes/r2000ic125l/visual/link_6.stl"/>
        </geometry>
        <xacro:material_fanuc_black />
      </visual>
      <collision>
        <origin xyz="0 0 0" rpy="0 0 0"/>
        <geometry>
          <mesh filename="package://fanuc_r2000ic_support/meshes/r2000ic125l/collision/link_6.stl"/>
        </geometry>
        <xacro:material_fanuc_black />
      </collision>
    </link>
    <link name="${prefix}tool0"/>
    <!-- end of link list -->
    <!-- joint list -->
    <joint name="${prefix}joint_1" type="revolute">
      <origin xyz="0 0 0.670" rpy="0 0 0"/>
      <parent link="${prefix}base_link"/>
      <child link="${prefix}link_1"/>
      <axis xyz="0 0 1"/>
      <limit lower="-${radians(185)}" upper="${radians(185)}" effort="0" velocity="${radians(130)}"/>
    </joint>
    <joint name="${prefix}joint_2" type="revolute">
      <origin xyz="0.312 0 0" rpy="0 0 0"/>
      <parent link="${prefix}link_1"/>
      <child link="${prefix}link_2"/>
      <axis xyz="0 1 0"/>
      <limit lower="-${radians(60)}" upper="${radians(76)}" effort="0" velocity="${radians(115)}"/>
    </joint>
    <joint name="${prefix}joint_3" type="revolute">
      <origin xyz="0 0 1.075" rpy="0 0 0"/>
      <parent link="${prefix}link_2"/>
      <child link="${prefix}link_3"/>
      <axis xyz="0 1 0"/>
      <limit lower="-${radians(121)}" upper="${radians(180)}" effort="0" velocity="${radians(125)}"/>
    </joint>
    <joint name="${prefix}joint_4" type="revolute">
      <origin xyz="0 0 0.225" rpy="0 0 0"/>
      <parent link="${prefix}link_3"/>
      <child link="${prefix}link_4"/>
      <axis xyz="1 0 0"/>
      <limit lower="-${radians(360)}" upper="${radians(360)}" effort="0" velocity="${radians(180)}"/>
    </joint>
    <joint name="${prefix}joint_5" type="revolute">
      <origin xyz="1.730 0 0" rpy="0 0 0"/>
      <parent link="${prefix}link_4"/>
      <child link="${prefix}link_5"/>
      <axis xyz="0 1 0"/>
      <limit lower="-${radians(125)}" upper="${radians(125)}" effort="0" velocity="${radians(180)}"/>
    </joint>
    <joint name="${prefix}joint_6" type="revolute">
      <origin xyz="0.215 0 0" rpy="0 0 0"/>
      <parent link="${prefix}link_5"/>
      <child link="${prefix}link_6"/>
      <axis xyz="1 0 0"/>
      <limit lower="-${radians(360)}" upper="${radians(360)}" effort="0" velocity="${radians(260)}"/>
    </joint>
    <joint name="${prefix}joint_6-tool0" type="fixed">
      <origin xyz="0 0 0" rpy="0 ${radians(90)} 0"/>
      <parent link="${prefix}link_6"/>
      <child link="${prefix}tool0"/>
    </joint>
    <!-- end of joint list -->
    <!-- ROS base_link to Robot Manufacturer World Coordinates transform -->
    <link name="${prefix}base"/>
    <joint name="${prefix}base_link-base" type="fixed">
      <origin xyz="0 0 0" rpy="${radians(180)} -${radians(90)} 0"/>
      <parent link="${prefix}base_link"/>
      <child link="${prefix}base"/>
    </joint>
  </xacro:macro>
</robot>
