<?xml version="1.0" encoding="utf-8" ?>
<!-- =================================================================================== -->
<!-- |    This document was autogenerated by xacro from r2000ic165f.xacro              | -->
<!-- |    EDITING THIS FILE BY HAND IS NOT RECOMMENDED                                 | -->
<!-- =================================================================================== -->
<robot name="fanuc_r2000ic165f">
  <!-- links: main serial chain -->
  <link name="base_link">
    <visual>
      <origin rpy="0 0 0" xyz="0 0 0"/>
      <geometry>
        <mesh filename="package://fanuc_r2000ic_support/meshes/r2000ic165f/visual/base_link.stl"/>
      </geometry>
      <material name="">
        <color rgba="0.4 0.4 0.4 1.0"/>
      </material>
    </visual>
    <collision>
      <origin rpy="0 0 0" xyz="0 0 0"/>
      <geometry>
        <mesh filename="package://fanuc_r2000ic_support/meshes/r2000ic165f/collision/base_link.stl"/>
      </geometry>
    </collision>
  </link>
  <link name="link_1">
    <visual>
      <origin rpy="0 0 0" xyz="0 0 0"/>
      <geometry>
        <mesh filename="package://fanuc_r2000ic_support/meshes/r2000ic165f/visual/link_1.stl"/>
      </geometry>
      <material name="">
        <color rgba="0.96 0.76 0.13 1.0"/>
      </material>
    </visual>
    <collision>
      <origin rpy="0 0 0" xyz="0 0 0"/>
      <geometry>
        <mesh filename="package://fanuc_r2000ic_support/meshes/r2000ic165f/collision/link_1.stl"/>
      </geometry>
    </collision>
  </link>
  <link name="link_2">
    <visual>
      <origin rpy="0 0 0" xyz="0 0 0"/>
      <geometry>
        <mesh filename="package://fanuc_r2000ic_support/meshes/r2000ic165f/visual/link_2.stl"/>
      </geometry>
      <material name="">
        <color rgba="0.96 0.76 0.13 1.0"/>
      </material>
    </visual>
    <collision>
      <origin rpy="0 0 0" xyz="0 0 0"/>
      <geometry>
        <mesh filename="package://fanuc_r2000ic_support/meshes/r2000ic165f/collision/link_2.stl"/>
      </geometry>
    </collision>
  </link>
  <link name="link_3">
    <visual>
      <origin rpy="0 0 0" xyz="0 0 0"/>
      <geometry>
        <mesh filename="package://fanuc_r2000ic_support/meshes/r2000ic165f/visual/link_3.stl"/>
      </geometry>
      <material name="">
        <color rgba="0.96 0.76 0.13 1.0"/>
      </material>
    </visual>
    <collision>
      <origin rpy="0 0 0" xyz="0 0 0"/>
      <geometry>
        <mesh filename="package://fanuc_r2000ic_support/meshes/r2000ic165f/collision/link_3.stl"/>
      </geometry>
    </collision>
  </link>
  <link name="link_4">
    <visual>
      <origin rpy="0 0 0" xyz="0 0 0"/>
      <geometry>
        <mesh filename="package://fanuc_r2000ic_support/meshes/r2000ic165f/visual/link_4.stl"/>
      </geometry>
      <material name="">
        <color rgba="0.96 0.76 0.13 1.0"/>
      </material>
    </visual>
    <collision>
      <origin rpy="0 0 0" xyz="0 0 0"/>
      <geometry>
        <mesh filename="package://fanuc_r2000ic_support/meshes/r2000ic165f/collision/link_4.stl"/>
      </geometry>
    </collision>
  </link>
  <link name="link_5">
    <visual>
      <origin rpy="0 0 0" xyz="0 0 0"/>
      <geometry>
        <mesh filename="package://fanuc_r2000ic_support/meshes/r2000ic165f/visual/link_5.stl"/>
      </geometry>
      <material name="">
        <color rgba="0.96 0.76 0.13 1.0"/>
      </material>
    </visual>
    <collision>
      <origin rpy="0 0 0" xyz="0 0 0"/>
      <geometry>
        <mesh filename="package://fanuc_r2000ic_support/meshes/r2000ic165f/collision/link_5.stl"/>
      </geometry>
    </collision>
  </link>
  <link name="link_6">
    <visual>
      <origin rpy="0 0 0" xyz="0 0 0"/>
      <geometry>
        <mesh filename="package://fanuc_r2000ic_support/meshes/r2000ic165f/visual/link_6.stl"/>
      </geometry>
      <material name="">
        <color rgba="0.15 0.15 0.15 1.0"/>
      </material>
    </visual>
    <collision>
      <origin rpy="0 0 0" xyz="0 0 0"/>
      <geometry>
        <mesh filename="package://fanuc_r2000ic_support/meshes/r2000ic165f/collision/link_6.stl"/>
      </geometry>
    </collision>
  </link>
  <link name="ef">
      <visual>
        <origin rpy="0 0 0" xyz="0 0 0"/>
        <geometry>
          <mesh filename="package://fanuc_r2000ic_support/meshes/r2000ic165f/visual/ef.stl"/>
        </geometry>
        <material name="">
          <color rgba="0.96 0.76 0.13 1.0"/>
        </material>
      </visual>
      <collision>
        <origin rpy="0 0 0" xyz="0 0 0"/>
        <geometry>
          <mesh filename="package://fanuc_r2000ic_support/meshes/r2000ic165f/collision/ef.stl"/>
        </geometry>
      </collision>
    </link>

<!--
<link name="part_link">
  <visual>
    <origin xyz="0 0 0" rpy="0 0 0"/>
    <geometry>
      <mesh filename="package://fanuc_r2000ic_support/meshes/r2000ic165f/visual/sandpart.stl"/>
    </geometry>
    <material name="">
      <color rgba="0.9 0.7 0.4 1.0"/>
    </material>
  </visual>

</link>

  <joint name="world_part_link" type="fixed">
      <parent link="base_link" />
      <child link="part_link" />
      <origin rpy="0 0 0" xyz="1.4 -0.4 0.6" />
  </joint>-->

<link name="gazebo_camera_link" />
<joint name="gazebo_camera_joint" type="fixed">
    <origin xyz="0.0 0.0 0.0" rpy="1.57 -1.57 0.0"/>
    <parent link="camera_link_optical"/>
    <child link="gazebo_camera_link"/>
</joint>
<link name="camera_link_optical" />
<joint name="camera_optical_joint" type="fixed">
    <origin xyz="-0.021 0.0797 0.06525" rpy="-0.7854 0 0"/>
    <parent link="link_6"/>
    <child link="camera_link_optical"/>
</joint>
<link name="camera_link" />
<joint name="camera_link_joint" type="fixed">
    <origin xyz="0.0 0.0 0.0" rpy="1.57 -1.57 0"/>
    <parent link="camera_link_optical"/>
    <child link="camera_link"/>
</joint>

  <!-- joints: main serial chain -->
  <joint name="joint_1" type="revolute">
    <origin rpy="0 0 0" xyz="0 0 0"/>
    <parent link="base_link"/>
    <child link="link_1"/>
    <axis xyz="0 0 1"/>
    <limit effort="0" lower="-3.22885911619" upper="3.22885911619" velocity="2.26892802759"/>
  </joint>
  <joint name="joint_2" type="revolute">
    <origin rpy="0 0 0" xyz="0.312 0 0.670"/>
    <parent link="link_1"/>
    <child link="link_2"/>
    <axis xyz="0 1 0"/>
    <limit effort="0" lower="-1.0471975512" upper="1.32645023152" velocity="2.00712863979"/>
  </joint>
  <joint name="joint_3" type="revolute">
    <origin rpy="0 0 0" xyz="0 0 1.075"/>
    <parent link="link_2"/>
    <child link="link_3"/>
    <axis xyz="0 -1 0"/>
    <limit effort="0" lower="-2.30383461263" upper="3.14159265359" velocity="2.18166156499"/>
  </joint>
  <joint name="joint_4" type="revolute">
    <origin rpy="0 0 0" xyz="0 0 0.225"/>
    <parent link="link_3"/>
    <child link="link_4"/>
    <axis xyz="-1 0 0"/>
    <limit effort="0" lower="-6.28318530718" upper="6.28318530718" velocity="3.14159265359"/>
  </joint>
  <joint name="joint_5" type="revolute">
    <origin rpy="0 0 0" xyz="1.280 0 0"/>
    <parent link="link_4"/>
    <child link="link_5"/>
    <axis xyz="0 -1 0"/>
    <limit effort="0" lower="-2.18166156499" upper="2.18166156499" velocity="3.14159265359"/>
  </joint>
  <joint name="joint_6" type="revolute">
    <origin rpy="0 0 0" xyz="0.215 0 0"/>
    <parent link="link_5"/>
    <child link="link_6"/>
    <axis xyz="-1 0 0"/>
    <limit effort="0" lower="-6.28318530718" upper="6.28318530718" velocity="4.53785605519"/>
  </joint>
  <!-- ROS-Industrial 'base' frame: base_link to Fanuc World Coordinates transform -->
  <link name="base"/>
  <joint name="base_link-base" type="fixed">
    <origin rpy="0 0 0" xyz="0 0 0.670"/>
    <parent link="base_link"/>
    <child link="base"/>
  </joint>
  <!-- ROS-Industrial 'flange' frame: attachment point for EEF models -->
  <link name="flange"/>
  <joint name="joint_6-flange" type="fixed">
    <origin rpy="0 0 0" xyz="0 0 0"/>
    <parent link="link_6"/>
    <child link="flange"/>
  </joint>
  <!-- ROS-Industrial 'tool0' frame: all-zeros tool frame -->
  <link name="tool0"/>
  <joint name="flange-tool0" type="fixed">
    <origin rpy="0 1.57079632679 0" xyz="0 0 0"/>
    <parent link="flange"/>
    <child link="tool0"/>
  </joint>
  <joint name="flange-ef" type="fixed">
      <origin rpy="3.14159265359 -1.57079632679 0" xyz="0 0 0"/>
      <parent link="flange"/>
      <child link="ef"/>
    </joint>



<transmission name="joint_1">
    <type>transmission_interface/SimpleTransmission</type>
    <joint name="joint_1">
        <hardwareInterface>hardware_interface/EffortJointInterface</hardwareInterface>
    </joint>
    <actuator name="joint_1_motor">
        <hardwareInterface>hardware_interface/EffortJointInterface</hardwareInterface>
        <mechanicalReduction>1</mechanicalReduction>
    </actuator>
</transmission>

<gazebo reference="base_link">
    <selfCollide>true</selfCollide>
</gazebo>
<gazebo reference="link_1">
    <selfCollide>true</selfCollide>
</gazebo>
<gazebo reference="link_2">
    <selfCollide>true</selfCollide>
</gazebo>
<gazebo reference="link_3">
    <selfCollide>true</selfCollide>
</gazebo>
<gazebo reference="link_4">
    <selfCollide>true</selfCollide>
</gazebo>
<gazebo reference="link_5">
    <selfCollide>true</selfCollide>
</gazebo>
<gazebo reference="link_6">
    <selfCollide>true</selfCollide>
</gazebo>
<gazebo reference="ef">
    <selfCollide>true</selfCollide>
</gazebo>
<gazebo reference="joint_1">
    <selfCollide>true</selfCollide>
</gazebo>
<gazebo reference="joint_2">
    <selfCollide>true</selfCollide>
</gazebo>
<gazebo reference="joint_3">
    <selfCollide>true</selfCollide>
</gazebo>


<gazebo reference="base">
    <selfCollide>true</selfCollide>
</gazebo>
<gazebo reference="flange">
    <selfCollide>true</selfCollide>
</gazebo>
<gazebo reference="tool0">
    <selfCollide>true</selfCollide>
</gazebo>
<gazebo reference="gazebo_camera_link">
    <sensor type="depth" name="sensor_name">
      <!-- Set always_on only sensor, not on plugin -->
      <always_on>1</always_on>
      <!-- Set update_rate only sensor, not on plugin -->
      <update_rate>5</update_rate>
      <camera name="camera_name">
        <image>
          <width>320</width>
          <height>200</height>
        </image>
        <distortion>
          <k1>-0.0</k1>
          <k2>0.0</k2>
          <k3>0.0</k3>
          <p1>-0.0</p1>
          <p2>-0.0</p2>
          <center>0.5 0.5</center>
        </distortion>
      </camera>
      <plugin name="plugin_name" filename="libgazebo_ros_camera.so">
        <!-- Change namespace, camera name and topics so:
             * Raw images are published to: /custom_ns/custom_camera/custom_image
             * Depth images are published to: /custom_ns/custom_camera/custom_image_depth
             * Raw image camera info is published to: /custom_ns/custom_camera/custom_info_raw
             * Depth image camera info is published to: /custom_ns/custom_camera/custom_info_depth
             * Point cloud is published to: /custom_ns/custom_camera/custom_points
        -->
        <ros>
          <namespace>custom_ns</namespace>
          <argument>camera/image_raw:=camera/custom_image</argument>
          <argument>camera/image_depth:=camera/custom_image_depth</argument>
          <argument>camera/camera_info:=camera/custom_info_raw</argument>
          <argument>camera/camera_info_depth:=camera/custom_info_depth</argument>
          <argument>camera/points:=camera/pointcloud</argument>
        </ros>
        <!-- Set camera name. If empty, defaults to sensor name (i.e. "sensor_name") -->
        <camera_name>camera</camera_name>
        <frame_name>camera_link_optical</frame_name>
        <!-- Set TF frame name. If empty, defaults to link name (i.e. "link_name") -->
        <hack_baseline>0.07</hack_baseline>
        <!-- No need to repeat distortion parameters or to set autoDistortion -->
         <min_depth>0.1</min_depth>
      </plugin>
    </sensor>
</gazebo>
<gazebo>
    <plugin name='gazebo_ros_joint_state_publisher' filename='libgazebo_ros_joint_state_publisher.so'>
      <ros>
          <namespace>/test</namespace>
          <argument>joint_states:=joint_states</argument>
      </ros>
      <update_rate>50</update_rate>
      <joint_name>joint_1</joint_name>
      <joint_name>joint_2</joint_name>
      <joint_name>joint_3</joint_name>
      <joint_name>joint_4</joint_name>
      <joint_name>joint_5</joint_name>
      <joint_name>joint_6</joint_name>
    </plugin>
    <plugin name='crs_gazebo_plugins_joint_pose_trajectory' filename='libcrs_gazebo_plugins_joint_pose_trajectory.so'>
        <ros>
          <namespace>sim</namespace>
          <argument>follow_joint_trajectory:=follow_joint_trajectory</argument>
        </ros>
        <update_rate>20</update_rate>
    </plugin>
</gazebo>



</robot>

