<?xml version="1.0" ?>
<!-- =================================================================================== -->
<!-- |    This document was autogenerated by xacro from /home/sizen/crs_ws_fanuc/install/fanuc_r2000ic_support/share/fanuc_r2000ic_support/urdf/r2000ic165f.xacro | -->
<!-- |    EDITING THIS FILE BY HAND IS NOT RECOMMENDED                                 | -->
<!-- =================================================================================== -->
<robot name="crs">
  <!-- Defining the colors used in this robot -->
  <material name="yellow">
    <color rgba="1 0.4 0 1"/>
  </material>
  <material name="black">
    <color rgba="0 0 0 0.95"/>
  </material>
  <material name="gray">
    <color rgba="0.75 0.75 0.75 1"/>
  </material>
  <!-- links: main serial chain -->
  <link name="world"/>
  <joint name="world_base_link" type="fixed">
    <parent link="world"/>
    <child link="base_link"/>
    <origin rpy="0 0 0" xyz="-2.5 0 0"/>
  </joint>
  <link name="base_link">
    <visual>
      <origin rpy="0 0 0" xyz="0 0 0"/>
      <geometry>
        <mesh filename="package://fanuc_r2000ic_support/meshes/r2000ic165f/visual/base_link.stl"/>
      </geometry>
      <material name="">
        <color rgba="0.4 0.4 0.4 1.0"/>
      </material>
    </visual>
    <collision>
      <origin rpy="0 0 0" xyz="0 0 0"/>
      <geometry>
        <mesh filename="package://fanuc_r2000ic_support/meshes/r2000ic165f/collision/base_link.stl"/>
      </geometry>
    </collision>
    <inertial>
      <mass value="10.0"/>
      <origin rpy="0.002688 0.004043 0.006103" xyz="-0.064613 -0.005314 0.100271"/>
      <inertia ixx="0.002695" ixy="0.000023" ixz="0.000157" iyy="0.004043" iyz="0.000023" izz="0.006096"/>
    </inertial>
  </link>
  <link name="link_1">
    <visual>
      <origin rpy="0 0 0" xyz="0 0 0"/>
      <geometry>
        <mesh filename="package://fanuc_r2000ic_support/meshes/r2000ic165f/visual/link_1.stl"/>
      </geometry>
      <material name="">
        <color rgba="0.96 0.76 0.13 1.0"/>
      </material>
    </visual>
    <collision>
      <origin rpy="0 0 0" xyz="0 0 0"/>
      <geometry>
        <mesh filename="package://fanuc_r2000ic_support/meshes/r2000ic165f/collision/link_1.stl"/>
      </geometry>
    </collision>
    <inertial>
      <mass value="5.0"/>
      <origin rpy="0.011358 0.019634 0.020073" xyz="0.010863 0.053239 0.523328"/>
      <inertia ixx="0.012932" ixy="0.003309" ixz=" -0.000331" iyy="0.018366" iyz="-0.000071" izz="0.019767"/>
    </inertial>
  </link>
  <link name="link_2">
    <visual>
      <origin rpy="0 0 0" xyz="0 0 0"/>
      <geometry>
        <mesh filename="package://fanuc_r2000ic_support/meshes/r2000ic165f/visual/link_2.stl"/>
      </geometry>
      <material name="">
        <color rgba="0.96 0.76 0.13 1.0"/>
      </material>
    </visual>
    <collision>
      <origin rpy="0 0 0" xyz="0 0 0"/>
      <geometry>
        <mesh filename="package://fanuc_r2000ic_support/meshes/r2000ic165f/collision/link_2.stl"/>
      </geometry>
    </collision>
    <inertial>
      <mass value="4.0"/>
      <origin rpy="0.001934 0.014381 0.015249" xyz="-0.001481 0.204359 0.436864"/>
      <inertia ixx="0.014390" ixy="0.000091" ixz="-0.000323" iyy="0.015120" iyz="-0.001213" izz="0.002053"/>
    </inertial>
  </link>
  <link name="link_3">
    <visual>
      <origin rpy="0 0 0" xyz="0 0 0"/>
      <geometry>
        <mesh filename="package://fanuc_r2000ic_support/meshes/r2000ic165f/visual/link_3.stl"/>
      </geometry>
      <material name="">
        <color rgba="0.96 0.76 0.13 1.0"/>
      </material>
    </visual>
    <collision>
      <origin rpy="0 0 0" xyz="0 0 0"/>
      <geometry>
        <mesh filename="package://fanuc_r2000ic_support/meshes/r2000ic165f/collision/link_3.stl"/>
      </geometry>
    </collision>
    <inertial>
      <mass value="4.0"/>
      <origin rpy="0.000964 0.001451 0.001518" xyz="0.059293 0.012994 0.109078"/>
      <inertia ixx="0.001451" ixy="0.000017" ixz="-0.000177" iyy="0.001441" iyz="0.000072" izz="0.001041"/>
    </inertial>
  </link>
  <link name="link_4">
    <visual>
      <origin rpy="0 0 0" xyz="0 0 0"/>
      <geometry>
        <mesh filename="package://fanuc_r2000ic_support/meshes/r2000ic165f/visual/link_4.stl"/>
      </geometry>
      <material name="">
        <color rgba="0.96 0.76 0.13 1.0"/>
      </material>
    </visual>
    <collision>
      <origin rpy="0 0 0" xyz="0 0 0"/>
      <geometry>
        <mesh filename="package://fanuc_r2000ic_support/meshes/r2000ic165f/collision/link_4.stl"/>
      </geometry>
    </collision>
    <inertial>
      <mass value="5.0"/>
      <origin rpy="0.000333 0.004282 0.004287" xyz="0.711733 -0.002537 -0.000643"/>
      <inertia ixx="0.000333" ixy="0.000044" ixz="0.000006" iyy="0.004287" iyz="-0.000000" izz="0.004282"/>
    </inertial>
  </link>
  <link name="link_5">
    <visual>
      <origin rpy="0 0 0" xyz="0 0 0"/>
      <geometry>
        <mesh filename="package://fanuc_r2000ic_support/meshes/r2000ic165f/visual/link_5.stl"/>
      </geometry>
      <material name="">
        <color rgba="0.96 0.76 0.13 1.0"/>
      </material>
    </visual>
    <collision>
      <origin rpy="0 0 0" xyz="0 0 0"/>
      <geometry>
        <mesh filename="package://fanuc_r2000ic_support/meshes/r2000ic165f/collision/link_5.stl"/>
      </geometry>
    </collision>
    <inertial>
      <mass value="8.0"/>
      <origin rpy="0.000078 0.000103 0.000118" xyz="0.042035 -0.024095 -0.001620"/>
      <inertia ixx="0.000088" ixy="-0.000012" ixz="0.000000" iyy="0.000094" iyz="0.000000" izz="0.000118"/>
    </inertial>
  </link>
  <link name="link_6">
    <visual>
      <origin rpy="0 0 0" xyz="0 0 0"/>
      <geometry>
        <mesh filename="package://fanuc_r2000ic_support/meshes/r2000ic165f/visual/link_6.stl"/>
      </geometry>
      <material name="">
        <color rgba="0.15 0.15 0.15 1.0"/>
      </material>
    </visual>
    <collision>
      <origin rpy="0 0 0" xyz="0 0 0"/>
      <geometry>
        <mesh filename="package://fanuc_r2000ic_support/meshes/r2000ic165f/collision/link_6.stl"/>
      </geometry>
    </collision>
    <inertial>
      <mass value="5.0"/>
      <origin rpy="0.000001 0.000001 0.000002" xyz="-0.018677 -0.000000 -0.000002"/>
      <inertia ixx="0.000002" ixy="0.000000" ixz="-0.000000" iyy="0.000001" iyz="0.000000" izz="0.000001"/>
    </inertial>
  </link>
  <link name="ef">
    <visual>
      <origin rpy="0 0 0" xyz="0 0 0"/>
      <geometry>
        <mesh filename="package://fanuc_r2000ic_support/meshes/r2000ic165f/visual/ef.stl"/>
      </geometry>
      <material name="">
        <color rgba="0.96 0.76 0.13 1.0"/>
      </material>
    </visual>
    <collision>
      <origin rpy="0 0 0" xyz="0 0 0"/>
      <geometry>
        <mesh filename="package://fanuc_r2000ic_support/meshes/r2000ic165f/collision/ef.stl"/>
      </geometry>
    </collision>
    <inertial>
      <mass value="3.0"/>
      <origin rpy="0.000082 0.000185 0.000195" xyz="0.0 0.0 0.0"/>
      <inertia ixx="0.000127" ixy="0.000000" ixz="0.000052" iyy="0.000194" iyz="0.000003" izz="0.000141"/>
    </inertial>
  </link>
  <!--mbot_base -->
  <link name="agv_base_link">
    <visual>
      <origin rpy="0 0 0" xyz="0 0 0"/>
      <geometry>
        <cylinder length="0.16" radius="0.20"/>
      </geometry>
      <material name="yellow">
        <color rgba="1 0.4 0 1"/>
      </material>
    </visual>
  </link>
  <joint name="agv_base_link" type="continuous">
    <origin rpy="0 0 0" xyz="0 0 0"/>
    <parent link="base_link"/>
    <child link="agv_base_link"/>
    <axis xyz="0 1 0"/>
  </joint>
  <joint name="left_wheel_joint" type="continuous">
    <origin rpy="0 0 0" xyz="0 0.19 -0.05"/>
    <parent link="base_link"/>
    <child link="left_wheel_link"/>
    <axis xyz="0 1 0"/>
  </joint>
  <link name="left_wheel_link">
    <visual>
      <origin rpy="1.5707 0 0" xyz="0 0 0"/>
      <geometry>
        <cylinder length="0.025" radius="0.06"/>
      </geometry>
      <material name="white">
        <color rgba="1 1 1 0.9"/>
      </material>
    </visual>
  </link>
  <joint name="right_wheel_joint" type="continuous">
    <origin rpy="0 0 0" xyz="0 -0.19 -0.05"/>
    <parent link="base_link"/>
    <child link="right_wheel_link"/>
    <axis xyz="0 1 0"/>
  </joint>
  <link name="right_wheel_link">
    <visual>
      <origin rpy="1.5707 0 0" xyz="0 0 0"/>
      <geometry>
        <cylinder length="0.025" radius="0.06"/>
      </geometry>
      <material name="white">
        <color rgba="1 1 1 0.9"/>
      </material>
    </visual>
  </link>
  <joint name="front_caster_joint" type="continuous">
    <origin rpy="0 0 0" xyz="0.18 0 -0.095"/>
    <parent link="base_link"/>
    <child link="front_caster_link"/>
    <axis xyz="0 1 0"/>
  </joint>
  <link name="front_caster_link">
    <visual>
      <origin rpy="0 0 0" xyz="0 0 0"/>
      <geometry>
        <sphere radius="0.015"/>
      </geometry>
      <material name="black">
        <color rgba="0 0 0 0.95"/>
      </material>
    </visual>
  </link>
  <joint name="back_caster_joint" type="continuous">
    <origin rpy="0 0 0" xyz="-0.18 0 -0.095"/>
    <parent link="base_link"/>
    <child link="back_caster_link"/>
    <axis xyz="0 1 0"/>
  </joint>
  <link name="back_caster_link">
    <visual>
      <origin rpy="0 0 0" xyz="0 0 0"/>
      <geometry>
        <sphere radius="0.015"/>
      </geometry>
      <material name="black">
        <color rgba="0 0 0 0.95"/>
      </material>
    </visual>
  </link>
  <!-- joints: main serial chain -->
  <joint name="joint_1" type="revolute">
    <origin rpy="0 0 0" xyz="0 0 0"/>
    <parent link="base_link"/>
    <child link="link_1"/>
    <axis xyz="0 0 1"/>
    <limit effort="0" lower="-3.2288591161895095" upper="3.2288591161895095" velocity="2.2689280275926285"/>
  </joint>
  <joint name="joint_2" type="revolute">
    <origin rpy="0 0 0" xyz="0.312 0 0.670"/>
    <parent link="link_1"/>
    <child link="link_2"/>
    <axis xyz="0 1 0"/>
    <limit effort="0" lower="-1.0471975511965976" upper="1.3264502315156905" velocity="2.007128639793479"/>
  </joint>
  <joint name="joint_3" type="revolute">
    <origin rpy="0 0 0" xyz="0 0 1.075"/>
    <parent link="link_2"/>
    <child link="link_3"/>
    <axis xyz="0 -1 0"/>
    <limit effort="0" lower="-2.303834612632515" upper="3.141592653589793" velocity="2.181661564992912"/>
  </joint>
  <joint name="joint_4" type="revolute">
    <origin rpy="0 0 0" xyz="0 0 0.225"/>
    <parent link="link_3"/>
    <child link="link_4"/>
    <axis xyz="-1 0 0"/>
    <limit effort="0" lower="-6.283185307179586" upper="6.283185307179586" velocity="3.141592653589793"/>
  </joint>
  <joint name="joint_5" type="revolute">
    <origin rpy="0 0 0" xyz="1.280 0 0"/>
    <parent link="link_4"/>
    <child link="link_5"/>
    <axis xyz="0 -1 0"/>
    <limit effort="0" lower="-2.181661564992912" upper="2.181661564992912" velocity="3.141592653589793"/>
  </joint>
  <joint name="joint_6" type="revolute">
    <origin rpy="0 0 0" xyz="0.215 0 0"/>
    <parent link="link_5"/>
    <child link="link_6"/>
    <axis xyz="-1 0 0"/>
    <limit effort="0" lower="-6.283185307179586" upper="6.283185307179586" velocity="4.537856055185257"/>
  </joint>
  <!-- ROS-Industrial 'base' frame: base_link to Fanuc World Coordinates transform -->
  <link name="base"/>
  <joint name="base_link-base" type="fixed">
    <origin rpy="0 0 0" xyz="0 0 0.670"/>
    <parent link="base_link"/>
    <child link="base"/>
  </joint>
  <!-- ROS-Industrial 'flange' frame: attachment point for EEF models -->
  <link name="flange"/>
  <joint name="joint_6-flange" type="fixed">
    <origin rpy="0 0 0" xyz="0 0 0"/>
    <parent link="link_6"/>
    <child link="flange"/>
  </joint>
  <!-- ROS-Industrial 'tool0' frame: all-zeros tool frame -->
  <link name="tool0"/>
  <joint name="flange-tool0" type="fixed">
    <origin rpy="0 1.5707963267948966 0" xyz="0 0 0"/>
    <parent link="link_6"/>
    <child link="tool0"/>
  </joint>
  <joint name="flange-ef" type="fixed">
    <origin rpy="3.141592653589793 -3.141592653589793 0" xyz="0 0 0"/>
    <parent link="tool0"/>
    <child link="ef"/>
  </joint>
  <link name="tcp"/>
  <joint name="tcp_ef" type="fixed">
    <origin rpy="5.53832e-13 -0.785398 0" xyz="-0.204433413 -7.32E-04 0.333181177"/>
    <parent link="ef"/>
    <child link="tcp"/>
  </joint>
  <link name="gazebo_camera_link">
    <collision>
      <origin rpy="0 0 0" xyz="0 0 0"/>
      <geometry>
        <box size="0.1 0.1 0.1"/>
      </geometry>
    </collision>
    <visual>
      <origin rpy="0 0 0" xyz="0 0 0"/>
      <geometry>
        <box size="0.1 0.1 0.1"/>
      </geometry>
      <material name="">
        <color rgba="0.96 0.76 0.13 1.0"/>
      </material>
    </visual>
    <inertial>
      <mass value="1e-5"/>
      <origin rpy="0 0 0" xyz="0 0 0"/>
      <inertia ixx="1e-6" ixy="0" ixz="0" iyy="1e-6" iyz="0" izz="1e-6"/>
    </inertial>
  </link>
  <joint name="gazebo_camera_joint" type="fixed">
    <origin rpy="1.57 -1.57 0" xyz="0.0 0.0 0.0"/>
    <parent link="camera_link_optical"/>
    <child link="gazebo_camera_link"/>
  </joint>
  <link name="camera_link_optical">

    </link>
  <joint name="camera_optical_joint" type="fixed">
    <origin rpy="0 0 0" xyz="0.1 0 0.2"/>
    <parent link="ef"/>
    <child link="camera_link_optical"/>
  </joint>
  <link name="camera_link"/>
  <joint name="camera_link_joint" type="fixed">
    <origin rpy="1.57 -1.57 0" xyz="0.0 0.0 0.0"/>
    <parent link="camera_link_optical"/>
    <child link="camera_link"/>
  </joint>
  <transmission name="trans_joint_1">
    <type>transmission_interface/SimpleTransmission</type>
    <joint name="joint_1">
      <hardwareInterface>hardware_interface/EffortJointInterface</hardwareInterface>
    </joint>
    <actuator name="joint_1_motor">
      <hardwareInterface>hardware_interface/EffortJointInterface</hardwareInterface>
      <mechanicalReduction>1</mechanicalReduction>
    </actuator>
  </transmission>
  <transmission name="trans_joint_2">
    <type>transmission_interface/SimpleTransmission</type>
    <joint name="joint_2">
      <hardwareInterface>hardware_interface/EffortJointInterface</hardwareInterface>
    </joint>
    <actuator name="joint_2_motor">
      <hardwareInterface>hardware_interface/EffortJointInterface</hardwareInterface>
      <mechanicalReduction>1</mechanicalReduction>
    </actuator>
  </transmission>
  <transmission name="trans_joint_3">
    <type>transmission_interface/SimpleTransmission</type>
    <joint name="joint_3">
      <hardwareInterface>hardware_interface/EffortJointInterface</hardwareInterface>
    </joint>
    <actuator name="joint_3_motor">
      <hardwareInterface>hardware_interface/EffortJointInterface</hardwareInterface>
      <mechanicalReduction>1</mechanicalReduction>
    </actuator>
  </transmission>
  <transmission name="trans_joint_4">
    <type>transmission_interface/SimpleTransmission</type>
    <joint name="joint_4">
      <hardwareInterface>hardware_interface/EffortJointInterface</hardwareInterface>
    </joint>
    <actuator name="joint_4_motor">
      <hardwareInterface>hardware_interface/EffortJointInterface</hardwareInterface>
      <mechanicalReduction>1</mechanicalReduction>
    </actuator>
  </transmission>
  <transmission name="trans_joint_5">
    <type>transmission_interface/SimpleTransmission</type>
    <joint name="joint_5">
      <hardwareInterface>hardware_interface/EffortJointInterface</hardwareInterface>
    </joint>
    <actuator name="joint_5_motor">
      <hardwareInterface>hardware_interface/EffortJointInterface</hardwareInterface>
      <mechanicalReduction>1</mechanicalReduction>
    </actuator>
  </transmission>
  <transmission name="trans_joint_6">
    <type>transmission_interface/SimpleTransmission</type>
    <joint name="joint_6">
      <hardwareInterface>hardware_interface/EffortJointInterface</hardwareInterface>
    </joint>
    <actuator name="joint_6_motor">
      <hardwareInterface>hardware_interface/EffortJointInterface</hardwareInterface>
      <mechanicalReduction>1</mechanicalReduction>
    </actuator>
  </transmission>
  <gazebo reference="base_link">
    <selfCollide>true</selfCollide>
  </gazebo>
  <gazebo reference="link_1">
    <selfCollide>true</selfCollide>
  </gazebo>
  <gazebo reference="link_2">
    <selfCollide>true</selfCollide>
  </gazebo>
  <gazebo reference="link_3">
    <selfCollide>true</selfCollide>
  </gazebo>
  <gazebo reference="link_4">
    <selfCollide>true</selfCollide>
  </gazebo>
  <gazebo reference="link_5">
    <selfCollide>true</selfCollide>
  </gazebo>
  <gazebo reference="link_6">
    <selfCollide>true</selfCollide>
  </gazebo>
  <gazebo reference="ef">
    <selfCollide>true</selfCollide>
  </gazebo>
  <gazebo reference="tool0">
    <selfCollide>true</selfCollide>
  </gazebo>
  <gazebo reference="flange">
    <selfCollide>true</selfCollide>
  </gazebo>
  <gazebo reference="gazebo_camera_link">
    <sensor name="sensor_name" type="depth">
      <!-- Set always_on only sensor, not on plugin -->
      <always_on>1</always_on>
      <!-- Set update_rate only sensor, not on plugin -->
      <update_rate>5</update_rate>
      <camera name="camera_name">
        <image>
          <width>320</width>
          <height>200</height>
        </image>
        <distortion>
          <k1>-0.0</k1>
          <k2>0.0</k2>
          <k3>0.0</k3>
          <p1>-0.0</p1>
          <p2>-0.0</p2>
          <center>0.5 0.5</center>
        </distortion>
      </camera>
      <plugin filename="libgazebo_ros_camera.so" name="plugin_name">
        <!-- Change namespace, camera name and topics so:
                 * Raw images are published to: /custom_ns/custom_camera/custom_image
                 * Depth images are published to: /custom_ns/custom_camera/custom_image_depth
                 * Raw image camera info is published to: /custom_ns/custom_camera/custom_info_raw
                 * Depth image camera info is published to: /custom_ns/custom_camera/custom_info_depth
                 * Point cloud is published to: /custom_ns/custom_camera/custom_points
            -->
        <ros>
          <namespace>custom_ns</namespace>
          <argument>camera/image_raw:=camera/custom_image</argument>
          <argument>camera/image_depth:=camera/custom_image_depth</argument>
          <argument>camera/camera_info:=camera/custom_info_raw</argument>
          <argument>camera/camera_info_depth:=camera/custom_info_depth</argument>
          <argument>camera/points:=camera/pointcloud</argument>
        </ros>
        <!-- Set camera name. If empty, defaults to sensor name (i.e. "sensor_name") -->
        <camera_name>camera</camera_name>
        <frame_name>camera_link_optical</frame_name>
        <!-- Set TF frame name. If empty, defaults to link name (i.e. "link_name") -->
        <hack_baseline>0.07</hack_baseline>
        <!-- No need to repeat distortion parameters or to set autoDistortion -->
        <min_depth>0.1</min_depth>
      </plugin>
    </sensor>
  </gazebo>
  <gazebo>
    <plugin filename="libgazebo_ros_joint_state_publisher.so" name="gazebo_ros_joint_state_publisher">
      <ros>
        <namespace>/test</namespace>
        <argument>joint_states:=joint_states</argument>
      </ros>
      <update_rate>50</update_rate>
      <joint_name>joint_1</joint_name>
      <joint_name>joint_2</joint_name>
      <joint_name>joint_3</joint_name>
      <joint_name>joint_4</joint_name>
      <joint_name>joint_5</joint_name>
      <joint_name>joint_6</joint_name>
    </plugin>
    <plugin filename="libcrs_gazebo_plugins_joint_pose_trajectory.so" name="crs_gazebo_plugins_joint_pose_trajectory">
      <ros>
        <namespace>sim</namespace>
        <argument>follow_joint_trajectory:=follow_joint_trajectory</argument>
      </ros>
      <update_rate>20</update_rate>
    </plugin>
  </gazebo>
</robot>
